{
  size: [11, 11, 11],
  entities: [],
  blocks: [
    {pos:[0,0,5],state:8},
    {pos:[1,0,2],state:9},
    {pos:[1,0,3],state:8},
    {pos:[1,0,4],state:8},
    {pos:[1,0,5],state:8},
    {pos:[1,0,6],state:10},
    {pos:[1,0,7],state:10},
    {pos:[1,0,8],state:8},
    {pos:[1,1,5],state:8},
    {pos:[2,0,1],state:8},
    {pos:[2,0,2],state:9},
    {pos:[2,0,3],state:9},
    {pos:[2,0,4],state:10},
    {pos:[2,0,5],state:10},
    {pos:[2,0,6],state:8},
    {pos:[2,0,7],state:8},
    {pos:[2,0,8],state:8},
    {pos:[2,0,9],state:8},
    {pos:[2,1,3],state:8},
    {pos:[2,1,4],state:9},
    {pos:[2,1,5],state:8},
    {pos:[2,1,6],state:8},
    {pos:[2,1,7],state:10},
    {pos:[2,2,5],state:8},
    {pos:[2,5,5],state:6},
    {pos:[3,0,1],state:8},
    {pos:[3,0,2],state:9},
    {pos:[3,0,3],state:8},
    {pos:[3,0,4],state:8},
    {pos:[3,0,5],state:8},
    {pos:[3,0,6],state:9},
    {pos:[3,0,7],state:8},
    {pos:[3,0,8],state:8},
    {pos:[3,0,9],state:9},
    {pos:[3,1,2],state:8},
    {pos:[3,1,3],state:8},
    {pos:[3,1,4],state:9},
    {pos:[3,1,5],state:8},
    {pos:[3,1,6],state:8},
    {pos:[3,1,7],state:8},
    {pos:[3,1,8],state:8},
    {pos:[3,2,3],state:9},
    {pos:[3,2,4],state:8},
    {pos:[3,2,5],state:8},
    {pos:[3,2,6],state:8},
    {pos:[3,2,7],state:9},
    {pos:[3,3,4],state:1},
    {pos:[3,3,5],state:7},
    {pos:[3,3,6],state:1},
    {pos:[3,4,3],state:1},
    {pos:[3,4,4],state:7},
    {pos:[3,4,5],state:7},
    {pos:[3,4,6],state:1},
    {pos:[3,4,7],state:7},
    {pos:[3,5,3],state:1},
    {pos:[3,5,4],state:1},
    {pos:[3,5,6],state:1},
    {pos:[3,5,7],state:1},
    {pos:[3,6,3],state:1},
    {pos:[3,6,4],state:1},
    {pos:[3,6,5],state:1},
    {pos:[3,6,6],state:7},
    {pos:[3,6,7],state:7},
    {pos:[3,7,4],state:7},
    {pos:[3,7,5],state:7},
    {pos:[3,7,6],state:1},
    {pos:[4,0,1],state:9},
    {pos:[4,0,2],state:8},
    {pos:[4,0,3],state:10},
    {pos:[4,0,4],state:8},
    {pos:[4,0,5],state:8},
    {pos:[4,0,6],state:8},
    {pos:[4,0,7],state:8},
    {pos:[4,0,8],state:8},
    {pos:[4,0,9],state:8},
    {pos:[4,1,2],state:9},
    {pos:[4,1,3],state:9},
    {pos:[4,1,4],state:9},
    {pos:[4,1,5],state:8},
    {pos:[4,1,6],state:10},
    {pos:[4,1,7],state:9},
    {pos:[4,1,8],state:8},
    {pos:[4,2,3],state:9},
    {pos:[4,2,4],state:8},
    {pos:[4,2,5],state:8},
    {pos:[4,2,6],state:9},
    {pos:[4,2,7],state:8},
    {pos:[4,3,3],state:1},
    {pos:[4,3,4],state:1},
    {pos:[4,3,5],state:7},
    {pos:[4,3,6],state:1},
    {pos:[4,3,7],state:7},
    {pos:[4,4,3],state:7},
    {pos:[4,4,4],state:2},
    {pos:[4,4,5],state:2},
    {pos:[4,4,6],state:2},
    {pos:[4,4,7],state:1},
    {pos:[4,5,3],state:7},
    {pos:[4,5,7],state:1},
    {pos:[4,6,3],state:1},
    {pos:[4,6,7],state:1},
    {pos:[4,7,3],state:1},
    {pos:[4,7,4],state:1},
    {pos:[4,7,5],state:1},
    {pos:[4,7,6],state:7},
    {pos:[4,7,7],state:1},
    {pos:[5,0,0],state:8},
    {pos:[5,0,1],state:9},
    {pos:[5,0,2],state:8},
    {pos:[5,0,3],state:9},
    {pos:[5,0,4],state:9},
    {pos:[5,0,5],state:8},
    {pos:[5,0,6],state:10},
    {pos:[5,0,7],state:10},
    {pos:[5,0,8],state:9},
    {pos:[5,0,9],state:8},
    {pos:[5,0,10],state:8},
    {pos:[5,1,1],state:8},
    {pos:[5,1,2],state:10},
    {pos:[5,1,3],state:9},
    {pos:[5,1,4],state:8},
    {pos:[5,1,5],state:8},
    {pos:[5,1,6],state:9},
    {pos:[5,1,7],state:8},
    {pos:[5,1,8],state:9},
    {pos:[5,1,9],state:8},
    {pos:[5,2,2],state:9},
    {pos:[5,2,3],state:8},
    {pos:[5,2,4],state:8},
    {pos:[5,2,5],state:8},
    {pos:[5,2,6],state:8},
    {pos:[5,2,7],state:8},
    {pos:[5,2,8],state:8},
    {pos:[5,3,3],state:1},
    {pos:[5,3,4],state:1},
    {pos:[5,3,6],state:1},
    {pos:[5,3,7],state:1},
    {pos:[5,4,3],state:7},
    {pos:[5,4,4],state:2},
    {pos:[5,4,5],state:2},
    {pos:[5,4,6],state:2},
    {pos:[5,4,7],state:1},
    {pos:[5,5,2],state:1},
    {pos:[5,5,5],state:4},
    {pos:[5,5,8],state:1},
    {pos:[5,6,3],state:1},
    {pos:[5,6,5],state:3},
    {pos:[5,6,7],state:1},
    {pos:[5,7,3],state:1},
    {pos:[5,7,4],state:1},
    {pos:[5,7,5],state:4},
    {pos:[5,7,6],state:1},
    {pos:[5,7,7],state:7},
    {pos:[5,8,5],state:5},
    {pos:[6,0,1],state:8},
    {pos:[6,0,2],state:10},
    {pos:[6,0,3],state:10},
    {pos:[6,0,4],state:8},
    {pos:[6,0,5],state:8},
    {pos:[6,0,6],state:9},
    {pos:[6,0,7],state:8},
    {pos:[6,0,8],state:8},
    {pos:[6,0,9],state:8},
    {pos:[6,1,2],state:8},
    {pos:[6,1,3],state:10},
    {pos:[6,1,4],state:9},
    {pos:[6,1,5],state:8},
    {pos:[6,1,6],state:8},
    {pos:[6,1,7],state:8},
    {pos:[6,1,8],state:8},
    {pos:[6,2,3],state:10},
    {pos:[6,2,4],state:9},
    {pos:[6,2,5],state:8},
    {pos:[6,2,6],state:10},
    {pos:[6,2,7],state:9},
    {pos:[6,3,3],state:1},
    {pos:[6,3,4],state:1},
    {pos:[6,3,5],state:1},
    {pos:[6,3,6],state:1},
    {pos:[6,3,7],state:7},
    {pos:[6,4,3],state:7},
    {pos:[6,4,4],state:2},
    {pos:[6,4,5],state:2},
    {pos:[6,4,6],state:2},
    {pos:[6,4,7],state:1},
    {pos:[6,5,3],state:1},
    {pos:[6,5,7],state:1},
    {pos:[6,6,3],state:7},
    {pos:[6,6,7],state:7},
    {pos:[6,7,3],state:1},
    {pos:[6,7,4],state:1},
    {pos:[6,7,5],state:1},
    {pos:[6,7,6],state:1},
    {pos:[6,7,7],state:1},
    {pos:[7,0,1],state:9},
    {pos:[7,0,2],state:9},
    {pos:[7,0,3],state:9},
    {pos:[7,0,4],state:9},
    {pos:[7,0,5],state:9},
    {pos:[7,0,6],state:8},
    {pos:[7,0,7],state:9},
    {pos:[7,0,8],state:8},
    {pos:[7,0,9],state:8},
    {pos:[7,1,2],state:8},
    {pos:[7,1,3],state:9},
    {pos:[7,1,4],state:8},
    {pos:[7,1,5],state:8},
    {pos:[7,1,6],state:8},
    {pos:[7,1,7],state:9},
    {pos:[7,1,8],state:8},
    {pos:[7,2,3],state:8},
    {pos:[7,2,4],state:9},
    {pos:[7,2,5],state:8},
    {pos:[7,2,6],state:8},
    {pos:[7,2,7],state:10},
    {pos:[7,3,4],state:1},
    {pos:[7,3,5],state:1},
    {pos:[7,3,6],state:1},
    {pos:[7,4,3],state:1},
    {pos:[7,4,4],state:1},
    {pos:[7,4,5],state:1},
    {pos:[7,4,6],state:1},
    {pos:[7,4,7],state:1},
    {pos:[7,5,3],state:1},
    {pos:[7,5,4],state:7},
    {pos:[7,5,6],state:7},
    {pos:[7,5,7],state:7},
    {pos:[7,6,3],state:1},
    {pos:[7,6,4],state:1},
    {pos:[7,6,5],state:1},
    {pos:[7,6,6],state:1},
    {pos:[7,6,7],state:1},
    {pos:[7,7,4],state:7},
    {pos:[7,7,5],state:1},
    {pos:[7,7,6],state:1},
    {pos:[8,0,1],state:8},
    {pos:[8,0,2],state:9},
    {pos:[8,0,3],state:9},
    {pos:[8,0,4],state:9},
    {pos:[8,0,5],state:9},
    {pos:[8,0,6],state:10},
    {pos:[8,0,7],state:8},
    {pos:[8,0,8],state:8},
    {pos:[8,0,9],state:8},
    {pos:[8,1,3],state:8},
    {pos:[8,1,4],state:10},
    {pos:[8,1,5],state:9},
    {pos:[8,1,6],state:10},
    {pos:[8,1,7],state:8},
    {pos:[8,2,5],state:9},
    {pos:[8,5,5],state:1},
    {pos:[9,0,2],state:8},
    {pos:[9,0,3],state:8},
    {pos:[9,0,4],state:10},
    {pos:[9,0,5],state:8},
    {pos:[9,0,6],state:10},
    {pos:[9,0,7],state:8},
    {pos:[9,0,8],state:8},
    {pos:[9,1,5],state:8},
    {pos:[10,0,5],state:10}
  ],
  palette: [
    {Name:"minecraft:air"},
    {Name:"ae2:sky_stone_block"},
    {Name:"ae2lt:silicon_block"},
    {Name:"ae2lt:overload_crystal_block"},
    {Name:"ae2lt:overload_machine_frame"},
    {Name:"ae2lt:lightning_collector"},
    {Name:"ae2:quartz_glass"},
    {Name:"minecraft:iron_block"},
    {Name:"minecraft:basalt"},
    {Name:"minecraft:magma_block"},
    {Name:"minecraft:obsidian"},
    {Name:"ae2lt:overloaded_cable"}
  ],
  DataVersion: 3463
}